Workbook

Sheet Raw_Data
A1: Case_ID | B1: Date_Received | C1: Channel | D1: Location | E1: Sector | F1: Feedback_Type | G1: Sensitivity | H1: Gender | I1: Age_Group | J1: Status | K1: Date_Closed | L1: Feedback_Note
A2: CFM-2026-0367 | B2: 46193 | C2: In-Person at Distribution | D2: Nuseirat | E2: Food Security | F2: Request for Information | G2: Non-Sensitive | H2: Female | I2: 60+ | J2: Closed | K2: 46203
A3: CFM-2026-0154 | B3: 46150 | C3: Phone Hotline | D3: Khan Yunis | E3: Food Security | F3: Complaint | G3: Non-Sensitive | H3: Female | I3: 45-59 | J3: Closed | K3: 46153 | L3: Food parcel contents did not match the announced list.
A4: CFM-2026-0388 | B4: 46144 | C4: Suggestion Box | D4: Khan Yunis | E4: Shelter | F4: Suggestion | G4: Non-Sensitive | H4: Female | I4: 45-59 | J4: CLOSED | K4: 46151 | L4: Tarpaulin received is torn and does not cover the shelter area.
A5: CFM-2026-0498 | B5: 22/02/2026 | C5: Community Focal Point | D5: gaza city | E5: Health | F5: Sensitive Complaint | G5: Sensitive | H5: Female | I5: 30-44 | J5: Closed | K5: 46078 | L5: Sensitive case - details recorded separately by the focal point; not stored in this tracker.
A6: CFM-2026-0041 | B6: 46137 | C6: in-person at distribution | D6: deir al-balah | E6: Shelter | F6: Suggestion | G6: Non-Sensitive | H6: Female | I6: 45-59 | J6: Closed | K6: 46140 | L6: Requesting information about the criteria for shelter repair kits.
A7: CFM-2026-0198 | B7: 46223 | C7: in-person at distribution | D7: nuseirat | E7: Shelter | F7: Appreciation | G7: Non-Sensitive | H7: Male | I7: 30-44 | J7: Closed | K7: 46248 | L7: Requesting information about the criteria for shelter repair kits.
A8: CFM-2026-0459 | B8: 46082 | C8: Phone Hotline | D8: Deir al-Balah | E8: WASH | F8: Complaint | G8: Non-Sensitive | H8: Female | I8: 18-29 | J8: Closed | K8: 46087 | L8: Requesting additional jerrycans for a shared shelter of four families.
A9: CFM-2026-0488 | B9: 46196 | C9: Community Focal Point | D9: Gaza City | E9: Health | F9: Complaint | G9: Non-Sensitive | H9: F | I9: 45-59 | J9: Open | L9: Requesting a referral pathway for a family member with limited mobility.
A10: CFM-2026-0414 | B10: 46215 | C10: Help Desk | D10: Gaza City | E10: Food Security | F10: Complaint | G10: Non-Sensitive | H10: Male | I10: 45-59 | J10: Closed | K10: 46227 | L10: Asking how the beneficiary list for the next round is prepared.
A11: CFM-2026-0075 | B11: 46137 | C11: Suggestion Box | D11: Deir Al Balah | E11: Nutrition | F11: Request for Information | G11: Non-Sensitive | H11: F | I11: 30-44 | J11: Closed | K11: 46140 | L11: Requesting a screening session closer to the northern shelter.
A12: CFM-2026-0340 | B12: 46143 | C12: Focal Point | D12: Jabalia | E12: Health | F12: Complaint | G12: Non-Sensitive | H12: Female | I12: 18-29 | J12: closed | K12: 46160 | L12: Waiting time at the mobile clinic is long during afternoon hours.
A13: CFM-2026-0407 | B13: 46200 | C13: Suggestion Box | D13: nuseirat | E13: Nutrition | F13: Complaint | G13: Non-Sensitive | H13: Male | J13: Closed | K13: 21/07/2026 | L13: Requesting a screening session closer to the northern shelter.
A14: CFM-2026-0403 | B14: 46047 | C14: Help Desk | D14: Deir al-Balah | E14: Food Security | F14: Complaint | G14: Non-Sensitive | H14: Female | I14: 60+ | J14: Open | L14: Food parcel contents did not match the announced list.
A15: CFM-2026-0362 | B15: 46172 | C15: Suggestion Box | D15: Nuseirat | E15: Food Security | F15: Complaint | G15: Non-Sensitive | H15: Male | I15: 45-59 | J15: Closed | K15: 46198 | L15: Thanking the team for organising the last distribution well.
A16: CFM-2026-0168 | B16: 46160 | C16: Phone Hotline | D16: Jabalia | E16: Nutrition | F16: Sensitive Complaint | G16: Sensitive | H16: M | I16: Under 18 | J16: Open | L16: Sensitive case - details recorded separately by the focal point; not stored in this tracker.
A17: CFM-2026-0116 | B17: 46088 | C17: Help Desk | D17: Gaza City | E17: Shelter | F17: Appreciation | G17: Non-Sensitive | H17: Male | I17: 30-44 | J17: In Progress | L17: Tarpaulin received is torn and does not cover the shelter area.
A18: CFM-2026-0018 | B18: 46226 | C18: Community Focal Point | D18: khan yunis | E18: Nutrition | F18: Complaint | G18: Non-Sensitive | H18: Female | I18: 18-29 | J18: Closed | K18: 46243 | L18: Asking whether children above five are included in the screening.
A19: CFM-2026-0456 | B19: 46116 | C19: Community Focal Point | D19: Gaza City | E19: WASH | F19: Request for Information | G19: Non-Sensitive | H19: M | I19: 18-29 | J19: Closed | K19: 46132 | L19: Latrine at the site block needs cleaning and lighting at night.
A20: CFM-2026-0441 | B20: 46087 | C20: Help Desk | D20: Gaza City | E20: Food Security | F20: Complaint | G20: Non-Sensitive | H20: Male | I20: 30-44 | J20: In Progress | L20: Asking how the beneficiary list for the next round is prepared.
A21: CFM-2026-0010 | B21: 25/04/2026 | C21: In-Person at Distribution | D21: Khan Younis | E21: Food Security | F21: Complaint | G21: Non-Sensitive | H21: Female | I21: Under 18 | J21: CLOSED | K21: 46138 | L21: Food parcel contents did not match the announced list.
A22: CFM-2026-0058 | B22: 46093 | C22: Phone Hotline | D22: Deir Al Balah | E22: WASH | F22: Appreciation | G22: Non-Sensitive | H22: Male | I22: 18-29 | J22: Closed | K22: 46101 | L22: Water truck did not arrive at the agreed time for three consecutive days.
A23: CFM-2026-0447 | B23: 46054 | C23: Suggestion Box | D23: Gaza City | E23: WASH | F23: Complaint | G23: Non-Sensitive | H23: Female | I23: 45-59 | J23: Closed | K23: 46065 | L23: The queue at the water point is not organised and older people cannot wait.
A24: CFM-2026-0091 | B24: 46118 | C24: Suggestion Box | D24: Deir al-Balah | E24: Food Security | F24: Complaint | G24: Non-Sensitive | H24: Female | I24: 30-44 | J24: Closed | K24: 46124 | L24: Thanking the team for organising the last distribution well.
A25: CFM-2026-0123 | B25: 46056 | C25: Phone Hotline | D25: Rafah | E25: Shelter | F25: Appreciation | G25: Non-Sensitive | H25: Male | I25: 30-44 | J25: In Progress | L25: Tarpaulin received is torn and does not cover the shelter area.
A26: CFM-2026-0322 | B26: 46195 | C26: In-Person at Distribution | D26: Jabalia | E26: WASH | F26: Complaint | G26: Non-Sensitive | H26: Female | I26: 30-44 | J26: Closed | K26: 46199 | L26: Requesting additional jerrycans for a shared shelter of four families.
A27: CFM-2026-0206 | B27: 46061 | C27: Suggestion box | D27: Deir al-Balah | E27: Shelter | F27: Request for Information | G27: Non-Sensitive | H27: Male | I27: 60+ | J27: Closed | K27: 46074 | L27: Shelter kit delivered on time and the team explained the use clearly.
A28: CFM-2026-0359 | B28: 46103 | C28: Suggestion Box | D28: Gaza City | E28: WASH | F28: Appreciation | G28: Non-Sensitive | H28: Female | I28: 18-29 | J28: in progress | L28: Requesting additional jerrycans for a shared shelter of four families.
A29: CFM-2026-0377 | B29: 46189 | C29: Help Desk | D29: Gaza City | E29: Nutrition | F29: Appreciation | G29: Non-Sensitive | H29: Female | I29: 30-44 | J29: Referred | L29: Asking whether children above five are included in the screening.
A30: CFM-2026-0401 | B30: 46099 | C30: In-Person at Distribution | D30: Jabalia | E30: WASH | F30: Suggestion | G30: Non-Sensitive | H30: female | I30: 45-59 | J30: In-Progress | L30: Latrine at the site block needs cleaning and lighting at night.
A31: CFM-2026-0005 | B31: 46153 | C31: Phone Hotline | D31: Nuseirat | E31: Food Security | F31: Complaint | G31: Non-Sensitive | H31: Female | I31: Under 18 | J31: CLOSED | K31: 46154 | L31: Distribution point is far and transport cost is high for our family.
A32: CFM-2026-0406 | B32: 46068 | C32: Help Desk | D32: jabalia | E32: Shelter | F32: Appreciation | G32: Non-Sensitive | H32: Female | I32: Under 18 | J32: Closed | K32: 46069 | L32: Tarpaulin received is torn and does not cover the shelter area.
A33: CFM-2026-0419 | B33: 46227 | C33: Phone Hotline | D33: Rafah | E33: Shelter | F33: Complaint | G33: Non-Sensitive | H33: Male | I33: 45-59 | J33: Closed | K33: 46243
A34: CFM-2026-0302 | B34: 46143 | C34: In-Person at Distribution | D34: Deir Al Balah | E34: Food Security | F34: Appreciation | G34: Non-Sensitive | H34: Female | I34: 45-59 | J34: Open | K34: 46163 | L34: Distribution point is far and transport cost is high for our family.
A35: CFM-2026-0265 | B35: 46045 | C35: in-person at distribution | D35: Gaza City | E35: Health | F35: Complaint | G35: Non-Sensitive | H35: Male | I35: Under 18 | J35: CLOSED | K35: 46073 | L35: Waiting time at the mobile clinic is long during afternoon hours.
A36: CFM-2026-0249 | B36: 46061 | C36: help desk | D36: Rafah | F36: Complaint | G36: Non-Sensitive | H36: Female | I36: 30-44 | J36: Closed | K36: 46067 | L36: Requesting a referral pathway for a family member with limited mobility.
A37: CFM-2026-0390 | B37: 46057 | C37: In Person at Distribution | D37: Deir al-Balah | E37: WASH | F37: Sensitive Complaint | G37: Sensitive | H37: Male | I37: 30-44 | J37: In Progress | L37: Sensitive case - details recorded separately by the focal point; not stored in this tracker.
A38: CFM-2026-0101 | B38: 46162 | C38: In-Person at Distribution | D38: deir al-balah | E38: Shelter | F38: Request for Information | G38: Non-Sensitive | H38: prefer not to say | I38: 30-44 | J38: closed | K38: 46190 | L38: Requesting information about the criteria for shelter repair kits.
A39: CFM-2026-0290 | B39: 46069 | C39: community focal point | D39: nuseirat | E39: Health | F39: Complaint | G39: Non-Sensitive | H39: Female | I39: 45-59 | J39: Closed | K39: 46077 | L39: Waiting time at the mobile clinic is long during afternoon hours.
A40: CFM-2026-0173 | B40: 46053 | C40: Phone Hotline | D40: Gaza City | E40: Health | F40: Sensitive Complaint | G40: Sensitive | H40: Female | I40: 18-29 | J40: open | L40: Sensitive case - details recorded separately by the focal point; not stored in this tracker.
...

Sheet Reference_Lists
A1: CANONICAL VALUE LISTS - use these as the single source of truth when standardising Raw_Data
A3: Channel | C3: Location | E3: Sector | G3: Feedback_Type | I3: Sensitivity
A4: Help Desk | C4: Khan Yunis | E4: WASH | G4: Complaint | I4: Non-Sensitive
A5: Phone Hotline | C5: Rafah | E5: Food Security | G5: Request for Information | I5: Sensitive
A6: Suggestion Box | C6: Deir al-Balah | E6: Nutrition | G6: Suggestion
A7: Community Focal Point | C7: Gaza City | E7: Shelter | G7: Appreciation
A8: In-Person at Distribution | C8: Jabalia | E8: Health | G8: Sensitive Complaint
C9: Nuseirat
A11: Gender | C11: Age_Group | E11: Status | G11: Response-time standard (assumption set by you, not by any organisation)
A12: Female | C12: Under 18 | E12: Open | G12: Sensitivity | H12: Target_Response_Days
A13: Male | C13: 18-29 | E13: In Progress | G13: Sensitive | H13: 3
A14: Prefer not to say | C14: 30-44 | E14: Closed | G14: Non-Sensitive | H14: 15
C15: 45-59 | E15: Referred
C16: 60+
A21: VARIANT -> CANONICAL MAPPING (build your lookup against this table)
A22: Field | B22: Variant found in Raw_Data | C22: Canonical value
A23: Channel | B23: help desk | C23: Help Desk
A24: Channel | B24: Helpdesk | C24: Help Desk
A25: Channel | B25: HELP DESK | C25: Help Desk
A26: Channel | B26: Help Desk | C26: Help Desk
A27: Channel | B27: phone hotline | C27: Phone Hotline
A28: Channel | B28: Hotline | C28: Phone Hotline
A29: Channel | B29: Phone Hotline | C29: Phone Hotline
A30: Channel | B30: suggestion box | C30: Suggestion Box
A31: Channel | B31: Suggestion box | C31: Suggestion Box
A32: Channel | B32: community focal point | C32: Community Focal Point
A33: Channel | B33: Focal Point | C33: Community Focal Point
... A65: Status | B65: referred | C65: Referred

Sheet Build_Spec
A1: COMMUNITY FEEDBACK & COMPLAINTS DATA QUALITY TRACKER - BUILD SPECIFICATION
A2: This workbook contains synthetic practice data only. No real person, household or organisation is represented.
A3: Defects in Raw_Data were introduced deliberately so that the cleaning and quality-check work has something to find.
A5: SCOPE OF THIS EXERCISE - keep your claims inside this line
A6: In scope: PivotTables, INDEX/MATCH, COUNTIFS, SUMIFS, AVERAGEIFS, SUMPRODUCT, COUNTBLANK, UNIQUE, IFERROR, TRIM, PROPER, TEXT, DATE/DATEVALUE, Remove Duplicates, Data Validation, Conditional Formatting.
A7: Deliberately out of scope: Power Query, VBA and macros, Power Pivot and DAX, statistical modelling. Do not claim these anywhere.
A9: COMPLETED PHASE 1 - Clean_Data
A10: 1. Copy Raw_Data into a new sheet named Clean_Data. Never edit Raw_Data - it is your before state and your evidence.
A11: 2. Standardise Channel, Location, Gender and Status against Reference_Lists using a lookup on the variant-to-canonical table; wrap it in IFERROR so an unmatched value stays visible instead of breaking.
A12: 3. Strip stray spaces and fix casing with TRIM and PROPER before the lookup runs.
A13: 4. Convert text dates to real dates with a locale-safe DATE formula using extracted day, month and year components, then apply a DD/MM/YYYY number format to the whole column.
A14: 5. Remove exact duplicate cases. Decide and write down your rule: which of two identical Case_IDs you keep, and why.
... A42: The limits of the exercise: synthetic data, no real intake process behind it, and no organisational data-protection policy applied.

Sheet Data_Quality_Check
A1: COMMUNITY FEEDBACK & COMPLAINTS MECHANISM - DATA QUALITY REGISTER
A2: Self-directed MEAL data-quality practice project using synthetic data. Response-time targets are assumed for demonstration purposes and do not represent an organisation's official standards.
A3: Source: Clean_Data (CleanDataTable). Raw_Data is preserved unchanged. Surviving defects are measured and reported, never corrected, filled or imputed. This completed deliverable covers data cleaning, alignment hardening, quality checks and reconciliation; dashboard development is an optional future extension.
A5: SECTION 1 - DATA QUALITY REGISTER
A6: Check_ID | B6: Data_Quality_Dimension | C6: Data_Quality_Check | D6: Issue_Count | E6: Denominator | F6: Completeness_or_Rate | G6: Result_Status | H6: Programme_Action | I6: Formula_Explanation
A7: DQ-01 | B7: Completeness | C7: Sector not recorded | D7: =COUNTBLANK(Clean_Data!$E$2:$E$501) -> 22 | E7: =COUNTA(Clean_Data!$A$2:$A$501) -> 500 | F7: =IFERROR(1-D7/E7,"") -> 0.956 | G7: =IF(D7=0,"Pass","Review required") -> Review required | H7: Return the flagged records to the data-collection team for sector classification before any disaggregated reporting is issued. | I7: COUNTBLANK counts cells in the Sector column that are empty or return an empty string; the denominator is the count of Case_IDs in the cleaned table.
A8: DQ-02 | B8: Completeness | C8: Sensitivity classification not recorded | D8: =COUNTBLANK(Clean_Data!$G$2:$G$501) -> 15 | E8: =COUNTA(Clean_Data!$A$2:$A$501) -> 500 | F8: =IFERROR(1-D8/E8,"") -> 0.97 | G8: =IF(D8=0,"Pass","Review required") -> Review required | H8: Review classification with authorised staff: without it the correct response-time target cannot be applied and the case is excluded from performance assessment. | I8: COUNTBLANK over the Sensitivity column. Each blank propagates into Target_Response_Days as UNMATCHED, so this check and DQ-10 are linked.
A9: DQ-03 | B9: Completeness | C9: Age group not recorded | D9: =COUNTBLANK(Clean_Data!$I$2:$I$501) -> 18 | E9: =COUNTA(Clean_Data!$A$2:$A$501) -> 500 | F9: =IFERROR(1-D9/E9,"") -> 0.964 | G9: =IF(D9=0,"Pass","Review required") -> Review required | H9: Request completion at source where the respondent provided it; do not estimate age group for disaggregation. | I9: COUNTBLANK over the Age_Group column, expressed against the same record denominator as every other completeness check.
A10: DQ-04 | B10: Completeness | C10: Feedback note not recorded | D10: =COUNTBLANK(Clean_Data!$L$2:$L$501) -> 12 | E10: =COUNTA(Clean_Data!$A$2:$A$501) -> 500 | F10: =IFERROR(1-D10/E10,"") -> 0.976 | G10: =IF(D10=0,"Pass","Review required") -> Review required | H10: Check whether a non-sensitive summary can be completed; do not request sensitive narrative detail that the tracker is not designed to hold. | I10: COUNTBLANK over the Feedback_Note column. Sensitive cases deliberately carry a placeholder rather than narrative detail, so blanks here are a completeness issue, not a confidentiality one.
A11: DQ-05 | B11: Uniqueness | C11: Duplicate Case_ID records remaining (beyond first occurrence) | D11: =COUNTA(Clean_Data!$A$2:$A$501)-SUMPRODUCT(1/COUNTIF(Clean_Data!$A$2:$A$501,Clean_Data!$A$2:$A$501)) -> 0 | G11: =IF(D11=0,"Pass","Review required") -> Pass | H11: No duplicates are expected. If this count rises, re-open the de-duplication rule and verify the affected Case_IDs before reporting. | I11: Total records minus the distinct count. COUNTIF returns how many times each Case_ID appears, so 1/COUNTIF gives every duplicate group a combined weight of exactly 1; the difference is the number of rows beyond the first occurrence. Uses no dynamic-array function, so it works in every Excel version.
A12: DQ-06 | B12: Alignment | C12: Case_ID not aligned with linked source row | D12: =COUNTA(Clean_Data!$A$2:$A$501)-COUNTIF(Clean_Data!$Q$2:$Q$501,"ALIGNED") -> 0 | G12: =IF(D12=0,"Pass","Review required") -> Pass | H12: Suspend use of any affected row until the source link and the stable Case_ID are reconciled; do not report figures from a misaligned row. | I12: Counts every row whose Alignment_Check is not ALIGNED, so MISMATCH, MISSING ID and CHECK are all captured rather than only the mismatch label.
A13: DQ-07 | B13: Date logic | C13: Date_Closed earlier than Date_Received | D13: =SUMPRODUCT(--ISNUMBER(Clean_Data!$B$2:$B$501),--ISNUMBER(Clean_Data!$K$2:$K$501),--(Clean_Data!$K$2:$K$501<Clean_Data!$B$2:$B$501)) -> 11 | G13: =IF(D13=0,"Pass","Review required") -> Review required | H13: Verify the original receipt and closure dates against source records; correct only after source verification and record the change in an audit trail. | I13: SUMPRODUCT requires both dates to be true numeric dates before testing whether Date_Closed precedes Date_Received. The ISNUMBER guards matter: Excel ranks any text above any number, so a date left as text would otherwise be counted as an error or hide a real one.
A14: DQ-08 | B14: Status logic | C14: Status Closed with no Date_Closed | D14: =SUMPRODUCT((Clean_Data!$J$2:$J$501="Closed")*(Clean_Data!$K$2:$K$501="")) -> 10 | G14: =IF(D14=0,"Pass","Review required") -> Review required | H14: Confirm whether the case is genuinely closed and complete the closure documentation; these cases cannot enter response-time performance until resolved. | I14: SUMPRODUCT over two conditions: status equals Closed and the closure date is empty. This is the first exclusion reason in the reconciliation block.
A15: DQ-09 | B15: Status logic | C15: Status Open or In Progress carrying a Date_Closed | D15: =SUMPRODUCT(((Clean_Data!$J$2:$J$501="Open")+(Clean_Data!$J$2:$J$501="In Progress"))*(Clean_Data!$K$2:$K$501<>"")) -> 8 | G15: =IF(D15=0,"Pass","Review required") -> Review required | H15: Confirm with the responsible team whether the status or the closure date is incorrect before either field is used in reporting. | I15: The two status conditions are added inside the brackets so the expression behaves as OR, then multiplied by the test that a closure date exists. A single COUNTIFS cannot express OR across one column.
A16: DQ-10 | B16: Lookup integrity | C16: Target_Response_Days returning UNMATCHED | D16: =COUNTIF(Clean_Data!$N$2:$N$501,"UNMATCHED") -> 15 | G16: =IF(D16=0,"Pass","Review required") -> Review required | H16: Resolve the underlying Sensitivity classification; the lookup is behaving correctly and must not be forced to return a default target. | I16: COUNTIF for the visible UNMATCHED label written by the IFERROR wrapper in the lookup, so a failed match stays visible instead of collapsing to a blank.
A17: DQ-11 | B17: Formula integrity | C17: Formula errors in calculated fields | D17: =SUMPRODUCT(--ISERROR(Clean_Data!$M$2:$O$501)) -> 0 | G17: =IF(D17=0,"Pass","Review required") -> Pass | H17: No formula error is acceptable in a reporting field. Trace any error to its source before using the derived performance measures. | I17: ISERROR is evaluated across the three calculated columns at once and the double negative converts TRUE and FALSE into 1 and 0 for SUMPRODUCT to total.
A18: DQ-12 | B18: Conformity | C18: Categorical value outside the canonical reference lists | D18: =COUNTIF(Clean_Data!$C$2:$C$501,"UNMATCHED")+COUNTIF(Clean_Data!$D$2:$D$501,"UNMATCHED")+COUNTIF(Clean_Data!$H$2:$H$501,"UNMATCHED")+COUNTIF(Clean_Data!$J$2:$J$501,"UNMATCHED") -> 0 | G18: =IF(D18=0,"Pass","Review required") -> Pass | H18: If any value appears here, review the standardisation mapping and canonical lists; do not manually overwrite the cleaned record. | I18: Each standardised field returns the visible label UNMATCHED whenever its mapping fails. COUNTIF totals those visible exceptions across Channel, Location, Gender and Status.
A19: DQ-13 | B19: Date integrity | C19: Date values still stored as text after cleaning | D19: =SUMPRODUCT(--(Clean_Data!$B$2:$B$501<>""),--ISTEXT(Clean_Data!$B$2:$B$501))+SUMPRODUCT(--(Clean_Data!$K$2:$K$501<>""),--ISTEXT(Clean_Data!$K$2:$K$501)) -> 0 | G19: =IF(D19=0,"Pass","Review required") -> Pass | H19: Re-run the locale-safe date conversion on the flagged cells and verify the original entry before using the dates in response-time reporting. | I19: SUMPRODUCT counts only non-blank Date_Received and Date_Closed cells that still evaluate as text; a result of zero confirms that stored text dates were converted to real date values.
A20: SECTION 2 - TARGET-ASSESSMENT RECONCILIATION
C21: Metric | D21: Value | H21: Definition / basis
C22: Total Closed cases | D22: =COUNTIF(Clean_Data!$J$2:$J$501,"Closed") -> 289 | H22: Every record whose standardised status is Closed.
C23: Eligible for target assessment | D23: =SUMPRODUCT(--(Clean_Data!$J$2:$J$501="Closed"),--ISNUMBER(Clean_Data!$K$2:$K$501),--ISNUMBER(Clean_Data!$M$2:$M$501),--(Clean_Data!$M$2:$M$501>=0),--ISNUMBER(Clean_Data!$N$2:$N$501)) -> 259 | H23: Closed cases carrying a genuine numeric closure date, a numeric non-negative response time and a matched numeric response-time target - the four conditions that allow a verdict. Tested with ISNUMBER rather than against the UNMATCHED label, so a blank or text value can never pass as eligible.
C24: Within target | D24: =SUMPRODUCT(--(Clean_Data!$J$2:$J$501="Closed"),--(Clean_Data!$O$2:$O$501=TRUE())) -> 143 | H24: Eligible cases closed within the assumed response-time target.
C25: Outside target | D25: =SUMPRODUCT(--(Clean_Data!$J$2:$J$501="Closed"),--(Clean_Data!$O$2:$O$501=FALSE())) -> 116 | H25: Eligible cases closed after the assumed response-time target.
C26: Excluded from target assessment | D26: =D22-D23 -> 30 | H26: Total Closed minus eligible; these cases cannot be judged either way and must be reported separately, never dropped silently.
A28: MUTUALLY EXCLUSIVE EXCLUSION REASONS (applied in precedence order)
C29: 1. Closed with missing Date_Closed | D29: =SUMPRODUCT((Clean_Data!$J$2:$J$501="Closed")*(Clean_Data!$K$2:$K$501="")) -> 10 | H29: First in precedence: without a closure date no response time exists.
C30: 2. Negative Response_Days (date present) | D30: =COUNTIFS(Clean_Data!$J$2:$J$501,"Closed",Clean_Data!$K$2:$K$501,"<>",Clean_Data!$M$2:$M$501,"<0") -> 11 | H30: Second: a closure date earlier than receipt. Includes the one record that also lacks Sensitivity, which is why it is not counted again below.
C31: 3. Sensitivity unresolved (dates valid) | D31: =COUNTIFS(Clean_Data!$J$2:$J$501,"Closed",Clean_Data!$K$2:$K$501,"<>",Clean_Data!$M$2:$M$501,">=0",Clean_Data!$N$2:$N$501,"UNMATCHED") -> 9 | H31: Third: dates are sound but no response-time target could be assigned.
C32: 4. Other or unexpected reason | D32: =SUMPRODUCT(--(Clean_Data!$J$2:$J$501="Closed"),--(Clean_Data!$K$2:$K$501<>""),--(Clean_Data!$M$2:$M$501>=0),--(Clean_Data!$N$2:$N$501<>"UNMATCHED"),--(Clean_Data!$O$2:$O$501="NOT ASSESSED")) -> 0 | H32: Independently derived, not a residual: a case meeting all four eligibility conditions whose Within_Target still shows no verdict. Doubles as an integrity test between the arithmetic definition and the Within_Target column.
C33: Sum of exclusive exclusion reasons | D33: =SUM(D29:D32) -> 30 | H33: Must equal the excluded total above.
C34: Reconciliation difference (must be zero) | D34: =D22-D23-D33 -> 0 | H34: Total Closed minus eligible minus the sum of exclusive reasons. Any non-zero value means a closed case is unaccounted for.
A36: NON-ADDITIVE RAW COUNTS - OVERLAPPING, DO NOT SUM
C37: Closed with missing Date_Closed (raw) | D37: =SUMPRODUCT((Clean_Data!$J$2:$J$501="Closed")*(Clean_Data!$K$2:$K$501="")) -> 10
C38: Closed with negative Response_Days (raw) | D38: =COUNTIFS(Clean_Data!$J$2:$J$501,"Closed",Clean_Data!$M$2:$M$501,"<0") -> 11
C39: Closed with missing Sensitivity (raw) | D39: =SUMPRODUCT((Clean_Data!$J$2:$J$501="Closed")*(Clean_Data!$G$2:$G$501="")) -> 10
C40: Naive total of the three raw counts | D40: =SUM(D37:D39) -> 31 | H40: Shown only to demonstrate the double-count: one closed case carries both a negative Response_Days and a missing Sensitivity, so this figure overstates the true exclusion total by one.
A42: SECTION 3 - MANAGEMENT SUMMARY
C43: ="1. Total records assessed: "&TEXT(COUNTA(Clean_Data!$A$2:$A$501),"0")&" cleaned Community Feedback Mechanism cases. Duplicate records beyond the first occurrence: "&TEXT(D11,"0")&"; alignment exceptions: "&TEXT(D12,"0")&"." -> 1. Total records assessed: 500 cleaned Community Feedback Mechanism cases. Duplicate records beyond the first occurrence: 0; alignment exceptions: 0.
C44: ="2. Three priority issues: "&TEXT(D8,"0")&" cases lack Sensitivity, preventing assignment of the response-time target; "&TEXT(D13,"0")&" cases have closure dates earlier than receipt; and "&TEXT(D14,"0")&" Closed cases lack a closure date. In addition, Sector is missing on "&TEXT(D7,"0")&" cases, limiting disaggregated reporting." -> 2. Three priority issues: 15 cases lack Sensitivity, preventing assignment of the response-time target; 11 cases have closure dates earlier than receipt; and 10 Closed cases lack a closure date. In addition, Sector is missing on 22 cases, limiting disaggregated reporting.
...

Sheet Clean_Data
A1: Case_ID | B1: Date_Received | C1: Channel | D1: Location | E1: Sector | F1: Feedback_Type | G1: Sensitivity | H1: Gender | I1: Age_Group | J1: Status | K1: Date_Closed | L1: Feedback_Note | M1: Response_Days | N1: Target_Response_Days | O1: Within_Target | P1: Linked_Source_Case_ID | Q1: Alignment_Check
A2: CFM-2026-0367 | B2: =IF(Raw_Data!B2="","",IF(ISTEXT(Raw_Data!B2),IFERROR(DATE(VALUE(RIGHT(TRIM(Raw_Data!B2),4)),VALUE(MID(TRIM(Raw_Data!B2),4,2)),VALUE(LEFT(TRIM(Raw_Data!B2),2))),"CHECK"),Raw_Data!B2)) -> 46193 | C2: =IFERROR(INDEX(Reference_Lists!$C$23:$C$35,MATCH(PROPER(TRIM(Raw_Data!C2)),Reference_Lists!$B$23:$B$35,0)),"UNMATCHED") -> In-Person at Distribution | D2: =IFERROR(INDEX(Reference_Lists!$C$36:$C$50,MATCH(PROPER(TRIM(Raw_Data!D2)),Reference_Lists!$B$36:$B$50,0)),"UNMATCHED") -> Nuseirat | E2: =IF(Raw_Data!E2="","",Raw_Data!E2) -> Food Security | F2: =IF(Raw_Data!F2="","",Raw_Data!F2) -> Request for Information | G2: =IF(Raw_Data!G2="","",Raw_Data!G2) -> Non-Sensitive | H2: =IFERROR(INDEX(Reference_Lists!$C$51:$C$57,MATCH(PROPER(TRIM(Raw_Data!H2)),Reference_Lists!$B$51:$B$57,0)),"UNMATCHED") -> Female | I2: =IF(Raw_Data!I2="","",Raw_Data!I2) -> 60+ | J2: =IFERROR(INDEX(Reference_Lists!$C$58:$C$65,MATCH(PROPER(TRIM(Raw_Data!J2)),Reference_Lists!$B$58:$B$65,0)),"UNMATCHED") -> Closed | K2: =IF(Raw_Data!K2="","",IF(ISTEXT(Raw_Data!K2),IFERROR(DATE(VALUE(RIGHT(TRIM(Raw_Data!K2),4)),VALUE(MID(TRIM(Raw_Data!K2),4,2)),VALUE(LEFT(TRIM(Raw_Data!K2),2))),"CHECK"),Raw_Data!K2)) -> 46203 | L2: =IF(Raw_Data!L2="","",Raw_Data!L2) | M2: =IF(OR(B2="",K2=""),"",IFERROR(K2-B2,"CHECK")) -> 10 | N2: =IFERROR(INDEX(Reference_Lists!$H$13:$H$14,MATCH(G2,Reference_Lists!$G$13:$G$14,0)),"UNMATCHED") -> 15 | O2: =IF(AND(J2="Closed",ISNUMBER(M2),ISNUMBER(N2),M2>=0),M2<=N2,"NOT ASSESSED") -> TRUE | P2: =Raw_Data!A2 -> CFM-2026-0367 | Q2: =IFERROR(IF(OR($A2="",$P2=""),"MISSING ID",IF(EXACT($A2,$P2),"ALIGNED","MISMATCH")),"CHECK") -> ALIGNED
A3: CFM-2026-0154 | B3: =IF(Raw_Data!B3="","",IF(ISTEXT(Raw_Data!B3),IFERROR(DATE(VALUE(RIGHT(TRIM(Raw_Data!B3),4)),VALUE(MID(TRIM(Raw_Data!B3),4,2)),VALUE(LEFT(TRIM(Raw_Data!B3),2))),"CHECK"),Raw_Data!B3)) -> 46150 | C3: =IFERROR(INDEX(Reference_Lists!$C$23:$C$35,MATCH(PROPER(TRIM(Raw_Data!C3)),Reference_Lists!$B$23:$B$35,0)),"UNMATCHED") -> Phone Hotline | D3: =IFERROR(INDEX(Reference_Lists!$C$36:$C$50,MATCH(PROPER(TRIM(Raw_Data!D3)),Reference_Lists!$B$36:$B$50,0)),"UNMATCHED") -> Khan Yunis | E3: =IF(Raw_Data!E3="","",Raw_Data!E3) -> Food Security | F3: =IF(Raw_Data!F3="","",Raw_Data!F3) -> Complaint | G3: =IF(Raw_Data!G3="","",Raw_Data!G3) -> Non-Sensitive | H3: =IFERROR(INDEX(Reference_Lists!$C$51:$C$57,MATCH(PROPER(TRIM(Raw_Data!H3)),Reference_Lists!$B$51:$B$57,0)),"UNMATCHED") -> Female | I3: =IF(Raw_Data!I3="","",Raw_Data!I3) -> 45-59 | J3: =IFERROR(INDEX(Reference_Lists!$C$58:$C$65,MATCH(PROPER(TRIM(Raw_Data!J3)),Reference_Lists!$B$58:$B$65,0)),"UNMATCHED") -> Closed | K3: =IF(Raw_Data!K3="","",IF(ISTEXT(Raw_Data!K3),IFERROR(DATE(VALUE(RIGHT(TRIM(Raw_Data!K3),4)),VALUE(MID(TRIM(Raw_Data!K3),4,2)),VALUE(LEFT(TRIM(Raw_Data!K3),2))),"CHECK"),Raw_Data!K3)) -> 46153 | L3: =IF(Raw_Data!L3="","",Raw_Data!L3) -> Food parcel contents did not match the announced list. | M3: =IF(OR(B3="",K3=""),"",IFERROR(K3-B3,"CHECK")) -> 3 | N3: =IFERROR(INDEX(Reference_Lists!$H$13:$H$14,MATCH(G3,Reference_Lists!$G$13:$G$14,0)),"UNMATCHED") -> 15 | O3: =IF(AND(J3="Closed",ISNUMBER(M3),ISNUMBER(N3),M3>=0),M3<=N3,"NOT ASSESSED") -> TRUE | P3: =Raw_Data!A3 -> CFM-2026-0154 | Q3: =IFERROR(IF(OR($A3="",$P3=""),"MISSING ID",IF(EXACT($A3,$P3),"ALIGNED","MISMATCH")),"CHECK") -> ALIGNED
A4: CFM-2026-0388 | B4: =IF(Raw_Data!B4="","",IF(ISTEXT(Raw_Data!B4),IFERROR(DATE(VALUE(RIGHT(TRIM(Raw_Data!B4),4)),VALUE(MID(TRIM(Raw_Data!B4),4,2)),VALUE(LEFT(TRIM(Raw_Data!B4),2))),"CHECK"),Raw_Data!B4)) -> 46144 | C4: =IFERROR(INDEX(Reference_Lists!$C$23:$C$35,MATCH(PROPER(TRIM(Raw_Data!C4)),Reference_Lists!$B$23:$B$35,0)),"UNMATCHED") -> Suggestion Box | D4: =IFERROR(INDEX(Reference_Lists!$C$36:$C$50,MATCH(PROPER(TRIM(Raw_Data!D4)),Reference_Lists!$B$36:$B$50,0)),"UNMATCHED") -> Khan Yunis | E4: =IF(Raw_Data!E4="","",Raw_Data!E4) -> Shelter | F4: =IF(Raw_Data!F4="","",Raw_Data!F4) -> Suggestion | G4: =IF(Raw_Data!G4="","",Raw_Data!G4) -> Non-Sensitive | H4: =IFERROR(INDEX(Reference_Lists!$C$51:$C$57,MATCH(PROPER(TRIM(Raw_Data!H4)),Reference_Lists!$B$51:$B$57,0)),"UNMATCHED") -> Female | I4: =IF(Raw_Data!I4="","",Raw_Data!I4) -> 45-59 | J4: =IFERROR(INDEX(Reference_Lists!$C$58:$C$65,MATCH(PROPER(TRIM(Raw_Data!J4)),Reference_Lists!$B$58:$B$65,0)),"UNMATCHED") -> Closed | K4: =IF(Raw_Data!K4="","",IF(ISTEXT(Raw_Data!K4),IFERROR(DATE(VALUE(RIGHT(TRIM(Raw_Data!K4),4)),VALUE(MID(TRIM(Raw_Data!K4),4,2)),VALUE(LEFT(TRIM(Raw_Data!K4),2))),"CHECK"),Raw_Data!K4)) -> 46151 | L4: =IF(Raw_Data!L4="","",Raw_Data!L4) -> Tarpaulin received is torn and does not cover the shelter area. | M4: =IF(OR(B4="",K4=""),"",IFERROR(K4-B4,"CHECK")) -> 7 | N4: =IFERROR(INDEX(Reference_Lists!$H$13:$H$14,MATCH(G4,Reference_Lists!$G$13:$G$14,0)),"UNMATCHED") -> 15 | O4: =IF(AND(J4="Closed",ISNUMBER(M4),ISNUMBER(N4),M4>=0),M4<=N4,"NOT ASSESSED") -> TRUE | P4: =Raw_Data!A4 -> CFM-2026-0388 | Q4: =IFERROR(IF(OR($A4="",$P4=""),"MISSING ID",IF(EXACT($A4,$P4),"ALIGNED","MISMATCH")),"CHECK") -> ALIGNED
A5: CFM-2026-0498 | B5: =IF(Raw_Data!B5="","",IF(ISTEXT(Raw_Data!B5),IFERROR(DATE(VALUE(RIGHT(TRIM(Raw_Data!B5),4)),VALUE(MID(TRIM(Raw_Data!B5),4,2)),VALUE(LEFT(TRIM(Raw_Data!B5),2))),"CHECK"),Raw_Data!B5)) -> 46075 | C5: =IFERROR(INDEX(Reference_Lists!$C$23:$C$35,MATCH(PROPER(TRIM(Raw_Data!C5)),Reference_Lists!$B$23:$B$35,0)),"UNMATCHED") -> Community Focal Point | D5: =IFERROR(INDEX(Reference_Lists!$C$36:$C$50,MATCH(PROPER(TRIM(Raw_Data!D5)),Reference_Lists!$B$36:$B$50,0)),"UNMATCHED") -> Gaza City | E5: =IF(Raw_Data!E5="","",Raw_Data!E5) -> Health | F5: =IF(Raw_Data!F5="","",Raw_Data!F5) -> Sensitive Complaint | G5: =IF(Raw_Data!G5="","",Raw_Data!G5) -> Sensitive | H5: =IFERROR(INDEX(Reference_Lists!$C$51:$C$57,MATCH(PROPER(TRIM(Raw_Data!H5)),Reference_Lists!$B$51:$B$57,0)),"UNMATCHED") -> Female | I5: =IF(Raw_Data!I5="","",Raw_Data!I5) -> 30-44 | J5: =IFERROR(INDEX(Reference_Lists!$C$58:$C$65,MATCH(PROPER(TRIM(Raw_Data!J5)),Reference_Lists!$B$58:$B$65,0)),"UNMATCHED") -> Closed | K5: =IF(Raw_Data!K5="","",IF(ISTEXT(Raw_Data!K5),IFERROR(DATE(VALUE(RIGHT(TRIM(Raw_Data!K5),4)),VALUE(MID(TRIM(Raw_Data!K5),4,2)),VALUE(LEFT(TRIM(Raw_Data!K5),2))),"CHECK"),Raw_Data!K5)) -> 46078 | L5: =IF(Raw_Data!L5="","",Raw_Data!L5) -> Sensitive case - details recorded separately by the focal point; not stored in this tracker. | M5: =IF(OR(B5="",K5=""),"",IFERROR(K5-B5,"CHECK")) -> 3 | N5: =IFERROR(INDEX(Reference_Lists!$H$13:$H$14,MATCH(G5,Reference_Lists!$G$13:$G$14,0)),"UNMATCHED") -> 3 | O5: =IF(AND(J5="Closed",ISNUMBER(M5),ISNUMBER(N5),M5>=0),M5<=N5,"NOT ASSESSED") -> TRUE | P5: =Raw_Data!A5 -> CFM-2026-0498 | Q5: =IFERROR(IF(OR($A5="",$P5=""),"MISSING ID",IF(EXACT($A5,$P5),"ALIGNED","MISMATCH")),"CHECK") -> ALIGNED
A6: CFM-2026-0041 | B6: =IF(Raw_Data!B6="","",IF(ISTEXT(Raw_Data!B6),IFERROR(DATE(VALUE(RIGHT(TRIM(Raw_Data!B6),4)),VALUE(MID(TRIM(Raw_Data!B6),4,2)),VALUE(LEFT(TRIM(Raw_Data!B6),2))),"CHECK"),Raw_Data!B6)) -> 46137 | C6: =IFERROR(INDEX(Reference_Lists!$C$23:$C$35,MATCH(PROPER(TRIM(Raw_Data!C6)),Reference_Lists!$B$23:$B$35,0)),"UNMATCHED") -> In-Person at Distribution | D6: =IFERROR(INDEX(Reference_Lists!$C$36:$C$50,MATCH(PROPER(TRIM(Raw_Data!D6)),Reference_Lists!$B$36:$B$50,0)),"UNMATCHED") -> Deir al-Balah | E6: =IF(Raw_Data!E6="","",Raw_Data!E6) -> Shelter | F6: =IF(Raw_Data!F6="","",Raw_Data!F6) -> Suggestion | G6: =IF(Raw_Data!G6="","",Raw_Data!G6) -> Non-Sensitive | H6: =IFERROR(INDEX(Reference_Lists!$C$51:$C$57,MATCH(PROPER(TRIM(Raw_Data!H6)),Reference_Lists!$B$51:$B$57,0)),"UNMATCHED") -> Female | I6: =IF(Raw_Data!I6="","",Raw_Data!I6) -> 45-59 | J6: =IFERROR(INDEX(Reference_Lists!$C$58:$C$65,MATCH(PROPER(TRIM(Raw_Data!J6)),Reference_Lists!$B$58:$B$65,0)),"UNMATCHED") -> Closed | K6: =IF(Raw_Data!K6="","",IF(ISTEXT(Raw_Data!K6),IFERROR(DATE(VALUE(RIGHT(TRIM(Raw_Data!K6),4)),VALUE(MID(TRIM(Raw_Data!K6),4,2)),VALUE(LEFT(TRIM(Raw_Data!K6),2))),"CHECK"),Raw_Data!K6)) -> 46140 | L6: =IF(Raw_Data!L6="","",Raw_Data!L6) -> Requesting information about the criteria for shelter repair kits. | M6: =IF(OR(B6="",K6=""),"",IFERROR(K6-B6,"CHECK")) -> 3 | N6: =IFERROR(INDEX(Reference_Lists!$H$13:$H$14,MATCH(G6,Reference_Lists!$G$13:$G$14,0)),"UNMATCHED") -> 15 | O6: =IF(AND(J6="Closed",ISNUMBER(M6),ISNUMBER(N6),M6>=0),M6<=N6,"NOT ASSESSED") -> TRUE | P6: =Raw_Data!A6 -> CFM-2026-0041 | Q6: =IFERROR(IF(OR($A6="",$P6=""),"MISSING ID",IF(EXACT($A6,$P6),"ALIGNED","MISMATCH")),"CHECK") -> ALIGNED
A7: CFM-2026-0198 | B7: =IF(Raw_Data!B7="","",IF(ISTEXT(Raw_Data!B7),IFERROR(DATE(VALUE(RIGHT(TRIM(Raw_Data!B7),4)),VALUE(MID(TRIM(Raw_Data!B7),4,2)),VALUE(LEFT(TRIM(Raw_Data!B7),2))),"CHECK"),Raw_Data!B7)) -> 46223 | C7: =IFERROR(INDEX(Reference_Lists!$C$23:$C$35,MATCH(PROPER(TRIM(Raw_Data!C7)),Reference_Lists!$B$23:$B$35,0)),"UNMATCHED") -> In-Person at Distribution | D7: =IFERROR(INDEX(Reference_Lists!$C$36:$C$50,MATCH(PROPER(TRIM(Raw_Data!D7)),Reference_Lists!$B$36:$B$50,0)),"UNMATCHED") -> Nuseirat | E7: =IF(Raw_Data!E7="","",Raw_Data!E7) -> Shelter | F7: =IF(Raw_Data!F7="","",Raw_Data!F7) -> Appreciation | G7: =IF(Raw_Data!G7="","",Raw_Data!G7) -> Non-Sensitive | H7: =IFERROR(INDEX(Reference_Lists!$C$51:$C$57,MATCH(PROPER(TRIM(Raw_Data!H7)),Reference_Lists!$B$51:$B$57,0)),"UNMATCHED") -> Male | I7: =IF(Raw_Data!I7="","",Raw_Data!I7) -> 30-44 | J7: =IFERROR(INDEX(Reference_Lists!$C$58:$C$65,MATCH(PROPER(TRIM(Raw_Data!J7)),Reference_Lists!$B$58:$B$65,0)),"UNMATCHED") -> Closed | K7: =IF(Raw_Data!K7="","",IF(ISTEXT(Raw_Data!K7),IFERROR(DATE(VALUE(RIGHT(TRIM(Raw_Data!K7),4)),VALUE(MID(TRIM(Raw_Data!K7),4,2)),VALUE(LEFT(TRIM(Raw_Data!K7),2))),"CHECK"),Raw_Data!K7)) -> 46248 | L7: =IF(Raw_Data!L7="","",Raw_Data!L7) -> Requesting information about the criteria for shelter repair kits. | M7: =IF(OR(B7="",K7=""),"",IFERROR(K7-B7,"CHECK")) -> 25 | N7: =IFERROR(INDEX(Reference_Lists!$H$13:$H$14,MATCH(G7,Reference_Lists!$G$13:$G$14,0)),"UNMATCHED") -> 15 | O7: =IF(AND(J7="Closed",ISNUMBER(M7),ISNUMBER(N7),M7>=0),M7<=N7,"NOT ASSESSED") -> FALSE | P7: =Raw_Data!A7 -> CFM-2026-0198 | Q7: =IFERROR(IF(OR($A7="",$P7=""),"MISSING ID",IF(EXACT($A7,$P7),"ALIGNED","MISMATCH")),"CHECK") -> ALIGNED
A8: CFM-2026-0459 | B8: =IF(Raw_Data!B8="","",IF(ISTEXT(Raw_Data!B8),IFERROR(DATE(VALUE(RIGHT(TRIM(Raw_Data!B8),4)),VALUE(MID(TRIM(Raw_Data!B8),4,2)),VALUE(LEFT(TRIM(Raw_Data!B8),2))),"CHECK"),Raw_Data!B8)) -> 46082 | C8: =IFERROR(INDEX(Reference_Lists!$C$23:$C$35,MATCH(PROPER(TRIM(Raw_Data!C8)),Reference_Lists!$B$23:$B$35,0)),"UNMATCHED") -> Phone Hotline | D8: =IFERROR(INDEX(Reference_Lists!$C$36:$C$50,MATCH(PROPER(TRIM(Raw_Data!D8)),Reference_Lists!$B$36:$B$50,0)),"UNMATCHED") -> Deir al-Balah | E8: =IF(Raw_Data!E8="","",Raw_Data!E8) -> WASH | F8: =IF(Raw_Data!F8="","",Raw_Data!F8) -> Complaint | G8: =IF(Raw_Data!G8="","",Raw_Data!G8) -> Non-Sensitive | H8: =IFERROR(INDEX(Reference_Lists!$C$51:$C$57,MATCH(PROPER(TRIM(Raw_Data!H8)),Reference_Lists!$B$51:$B$57,0)),"UNMATCHED") -> Female | I8: =IF(Raw_Data!I8="","",Raw_Data!I8) -> 18-29 | J8: =IFERROR(INDEX(Reference_Lists!$C$58:$C$65,MATCH(PROPER(TRIM(Raw_Data!J8)),Reference_Lists!$B$58:$B$65,0)),"UNMATCHED") -> Closed | K8: =IF(Raw_Data!K8="","",IF(ISTEXT(Raw_Data!K8),IFERROR(DATE(VALUE(RIGHT(TRIM(Raw_Data!K8),4)),VALUE(MID(TRIM(Raw_Data!K8),4,2)),VALUE(LEFT(TRIM(Raw_Data!K8),2))),"CHECK"),Raw_Data!K8)) -> 46087 | L8: =IF(Raw_Data!L8="","",Raw_Data!L8) -> Requesting additional jerrycans for a shared shelter of four families. | M8: =IF(OR(B8="",K8=""),"",IFERROR(K8-B8,"CHECK")) -> 5 | N8: =IFERROR(INDEX(Reference_Lists!$H$13:$H$14,MATCH(G8,Reference_Lists!$G$13:$G$14,0)),"UNMATCHED") -> 15 | O8: =IF(AND(J8="Closed",ISNUMBER(M8),ISNUMBER(N8),M8>=0),M8<=N8,"NOT ASSESSED") -> TRUE | P8: =Raw_Data!A8 -> CFM-2026-0459 | Q8: =IFERROR(IF(OR($A8="",$P8=""),"MISSING ID",IF(EXACT($A8,$P8),"ALIGNED","MISMATCH")),"CHECK") -> ALIGNED
A9: CFM-2026-0488 | B9: =IF(Raw_Data!B9="","",IF(ISTEXT(Raw_Data!B9),IFERROR(DATE(VALUE(RIGHT(TRIM(Raw_Data!B9),4)),VALUE(MID(TRIM(Raw_Data!B9),4,2)),VALUE(LEFT(TRIM(Raw_Data!B9),2))),"CHECK"),Raw_Data!B9)) -> 46196 | C9: =IFERROR(INDEX(Reference_Lists!$C$23:$C$35,MATCH(PROPER(TRIM(Raw_Data!C9)),Reference_Lists!$B$23:$B$35,0)),"UNMATCHED") -> Community Focal Point | D9: =IFERROR(INDEX(Reference_Lists!$C$36:$C$50,MATCH(PROPER(TRIM(Raw_Data!D9)),Reference_Lists!$B$36:$B$50,0)),"UNMATCHED") -> Gaza City | E9: =IF(Raw_Data!E9="","",Raw_Data!E9) -> Health | F9: =IF(Raw_Data!F9="","",Raw_Data!F9) -> Complaint | G9: =IF(Raw_Data!G9="","",Raw_Data!G9) -> Non-Sensitive | H9: =IFERROR(INDEX(Reference_Lists!$C$51:$C$57,MATCH(PROPER(TRIM(Raw_Data!H9)),Reference_Lists!$B$51:$B$57,0)),"UNMATCHED") -> Female | I9: =IF(Raw_Data!I9="","",Raw_Data!I9) -> 45-59 | J9: =IFERROR(INDEX(Reference_Lists!$C$58:$C$65,MATCH(PROPER(TRIM(Raw_Data!J9)),Reference_Lists!$B$58:$B$65,0)),"UNMATCHED") -> Open | K9: =IF(Raw_Data!K9="","",IF(ISTEXT(Raw_Data!K9),IFERROR(DATE(VALUE(RIGHT(TRIM(Raw_Data!K9),4)),VALUE(MID(TRIM(Raw_Data!K9),4,2)),VALUE(LEFT(TRIM(Raw_Data!K9),2))),"CHECK"),Raw_Data!K9)) | L9: =IF(Raw_Data!L9="","",Raw_Data!L9) -> Requesting a referral pathway for a family member with limited mobility. | M9: =IF(OR(B9="",K9=""),"",IFERROR(K9-B9,"CHECK")) | N9: =IFERROR(INDEX(Reference_Lists!$H$13:$H$14,MATCH(G9,Reference_Lists!$G$13:$G$14,0)),"UNMATCHED") -> 15 | O9: =IF(AND(J9="Closed",ISNUMBER(M9),ISNUMBER(N9),M9>=0),M9<=N9,"NOT ASSESSED") -> NOT ASSESSED | P9: =Raw_Data!A9 -> CFM-2026-0488 | Q9: =IFERROR(IF(OR($A9="",$P9=""),"MISSING ID",IF(EXACT($A9,$P9),"ALIGNED","MISMATCH")),"CHECK") -> ALIGNED
A10: CFM-2026-0414 | B10: =IF(Raw_Data!B10="","",IF(ISTEXT(Raw_Data!B10),IFERROR(DATE(VALUE(RIGHT(TRIM(Raw_Data!B10),4)),VALUE(MID(TRIM(Raw_Data!B10),4,2)),VALUE(LEFT(TRIM(Raw_Data!B10),2))),"CHECK"),Raw_Data!B10)) -> 46215 | C10: =IFERROR(INDEX(Reference_Lists!$C$23:$C$35,MATCH(PROPER(TRIM(Raw_Data!C10)),Reference_Lists!$B$23:$B$35,0)),"UNMATCHED") -> Help Desk | D10: =IFERROR(INDEX(Reference_Lists!$C$36:$C$50,MATCH(PROPER(TRIM(Raw_Data!D10)),Reference_Lists!$B$36:$B$50,0)),"UNMATCHED") -> Gaza City | E10: =IF(Raw_Data!E10="","",Raw_Data!E10) -> Food Security | F10: =IF(Raw_Data!F10="","",Raw_Data!F10) -> Complaint | G10: =IF(Raw_Data!G10="","",Raw_Data!G10) -> Non-Sensitive | H10: =IFERROR(INDEX(Reference_Lists!$C$51:$C$57,MATCH(PROPER(TRIM(Raw_Data!H10)),Reference_Lists!$B$51:$B$57,0)),"UNMATCHED") -> Male | I10: =IF(Raw_Data!I10="","",Raw_Data!I10) -> 45-59 | J10: =IFERROR(INDEX(Reference_Lists!$C$58:$C$65,MATCH(PROPER(TRIM(Raw_Data!J10)),Reference_Lists!$B$58:$B$65,0)),"UNMATCHED") -> Closed | K10: =IF(Raw_Data!K10="","",IF(ISTEXT(Raw_Data!K10),IFERROR(DATE(VALUE(RIGHT(TRIM(Raw_Data!K10),4)),VALUE(MID(TRIM(Raw_Data!K10),4,2)),VALUE(LEFT(TRIM(Raw_Data!K10),2))),"CHECK"),Raw_Data!K10)) -> 46227 | L10: =IF(Raw_Data!L10="","",Raw_Data!L10) -> Asking how the beneficiary list for the next round is prepared. | M10: =IF(OR(B10="",K10=""),"",IFERROR(K10-B10,"CHECK")) -> 12 | N10: =IFERROR(INDEX(Reference_Lists!$H$13:$H$14,MATCH(G10,Reference_Lists!$G$13:$G$14,0)),"UNMATCHED") -> 15 | O10: =IF(AND(J10="Closed",ISNUMBER(M10),ISNUMBER(N10),M10>=0),M10<=N10,"NOT ASSESSED") -> TRUE | P10: =Raw_Data!A10 -> CFM-2026-0414 | Q10: =IFERROR(IF(OR($A10="",$P10=""),"MISSING ID",IF(EXACT($A10,$P10),"ALIGNED","MISMATCH")),"CHECK") -> ALIGNED
A11: CFM-2026-0075 | B11: =IF(Raw_Data!B11="","",IF(ISTEXT(Raw_Data!B11),IFERROR(DATE(VALUE(RIGHT(TRIM(Raw_Data!B11),4)),VALUE(MID(TRIM(Raw_Data!B11),4,2)),VALUE(LEFT(TRIM(Raw_Data!B11),2))),"CHECK"),Raw_Data!B11)) -> 46137 | C11: =IFERROR(INDEX(Reference_Lists!$C$23:$C$35,MATCH(PROPER(TRIM(Raw_Data!C11)),Reference_Lists!$B$23:$B$35,0)),"UNMATCHED") -> Suggestion Box | D11: =IFERROR(INDEX(Reference_Lists!$C$36:$C$50,MATCH(PROPER(TRIM(Raw_Data!D11)),Reference_Lists!$B$36:$B$50,0)),"UNMATCHED") -> Deir al-Balah | E11: =IF(Raw_Data!E11="","",Raw_Data!E11) -> Nutrition | F11: =IF(Raw_Data!F11="","",Raw_Data!F11) -> Request for Information | G11: =IF(Raw_Data!G11="","",Raw_Data!G11) -> Non-Sensitive | H11: =IFERROR(INDEX(Reference_Lists!$C$51:$C$57,MATCH(PROPER(TRIM(Raw_Data!H11)),Reference_Lists!$B$51:$B$57,0)),"UNMATCHED") -> Female | I11: =IF(Raw_Data!I11="","",Raw_Data!I11) -> 30-44 | J11: =IFERROR(INDEX(Reference_Lists!$C$58:$C$65,MATCH(PROPER(TRIM(Raw_Data!J11)),Reference_Lists!$B$58:$B$65,0)),"UNMATCHED") -> Closed | K11: =IF(Raw_Data!K11="","",IF(ISTEXT(Raw_Data!K11),IFERROR(DATE(VALUE(RIGHT(TRIM(Raw_Data!K11),4)),VALUE(MID(TRIM(Raw_Data!K11),4,2)),VALUE(LEFT(TRIM(Raw_Data!K11),2))),"CHECK"),Raw_Data!K11)) -> 46140 | L11: =IF(Raw_Data!L11="","",Raw_Data!L11) -> Requesting a screening session closer to the northern shelter. | M11: =IF(OR(B11="",K11=""),"",IFERROR(K11-B11,"CHECK")) -> 3 | N11: =IFERROR(INDEX(Reference_Lists!$H$13:$H$14,MATCH(G11,Reference_Lists!$G$13:$G$14,0)),"UNMATCHED") -> 15 | O11: =IF(AND(J11="Closed",ISNUMBER(M11),ISNUMBER(N11),M11>=0),M11<=N11,"NOT ASSESSED") -> TRUE | P11: =Raw_Data!A11 -> CFM-2026-0075 | Q11: =IFERROR(IF(OR($A11="",$P11=""),"MISSING ID",IF(EXACT($A11,$P11),"ALIGNED","MISMATCH")),"CHECK") -> ALIGNED
A12: CFM-2026-0340 | B12: =IF(Raw_Data!B12="","",IF(ISTEXT(Raw_Data!B12),IFERROR(DATE(VALUE(RIGHT(TRIM(Raw_Data!B12),4)),VALUE(MID(TRIM(Raw_Data!B12),4,2)),VALUE(LEFT(TRIM(Raw_Data!B12),2))),"CHECK"),Raw_Data!B12)) -> 46143 | C12: =IFERROR(INDEX(Reference_Lists!$C$23:$C$35,MATCH(PROPER(TRIM(Raw_Data!C12)),Reference_Lists!$B$23:$B$35,0)),"UNMATCHED") -> Community Focal Point | D12: =IFERROR(INDEX(Reference_Lists!$C$36:$C$50,MATCH(PROPER(TRIM(Raw_Data!D12)),Reference_Lists!$B$36:$B$50,0)),"UNMATCHED") -> Jabalia | E12: =IF(Raw_Data!E12="","",Raw_Data!E12) -> Health | F12: =IF(Raw_Data!F12="","",Raw_Data!F12) -> Complaint | G12: =IF(Raw_Data!G12="","",Raw_Data!G12) -> Non-Sensitive | H12: =IFERROR(INDEX(Reference_Lists!$C$51:$C$57,MATCH(PROPER(TRIM(Raw_Data!H12)),Reference_Lists!$B$51:$B$57,0)),"UNMATCHED") -> Female | I12: =IF(Raw_Data!I12="","",Raw_Data!I12) -> 18-29 | J12: =IFERROR(INDEX(Reference_Lists!$C$58:$C$65,MATCH(PROPER(TRIM(Raw_Data!J12)),Reference_Lists!$B$58:$B$65,0)),"UNMATCHED") -> Closed | K12: =IF(Raw_Data!K12="","",IF(ISTEXT(Raw_Data!K12),IFERROR(DATE(VALUE(RIGHT(TRIM(Raw_Data!K12),4)),VALUE(MID(TRIM(Raw_Data!K12),4,2)),VALUE(LEFT(TRIM(Raw_Data!K12),2))),"CHECK"),Raw_Data!K12)) -> 46160 | L12: =IF(Raw_Data!L12="","",Raw_Data!L12) -> Waiting time at the mobile clinic is long during afternoon hours. | M12: =IF(OR(B12="",K12=""),"",IFERROR(K12-B12,"CHECK")) -> 17 | N12: =IFERROR(INDEX(Reference_Lists!$H$13:$H$14,MATCH(G12,Reference_Lists!$G$13:$G$14,0)),"UNMATCHED") -> 15 | O12: =IF(AND(J12="Closed",ISNUMBER(M12),ISNUMBER(N12),M12>=0),M12<=N12,"NOT ASSESSED") -> FALSE | P12: =Raw_Data!A12 -> CFM-2026-0340 | Q12: =IFERROR(IF(OR($A12="",$P12=""),"MISSING ID",IF(EXACT($A12,$P12),"ALIGNED","MISMATCH")),"CHECK") -> ALIGNED
A13: CFM-2026-0407 | B13: =IF(Raw_Data!B13="","",IF(ISTEXT(Raw_Data!B13),IFERROR(DATE(VALUE(RIGHT(TRIM(Raw_Data!B13),4)),VALUE(MID(TRIM(Raw_Data!B13),4,2)),VALUE(LEFT(TRIM(Raw_Data!B13),2))),"CHECK"),Raw_Data!B13)) -> 46200 | C13: =IFERROR(INDEX(Reference_Lists!$C$23:$C$35,MATCH(PROPER(TRIM(Raw_Data!C13)),Reference_Lists!$B$23:$B$35,0)),"UNMATCHED") -> Suggestion Box | D13: =IFERROR(INDEX(Reference_Lists!$C$36:$C$50,MATCH(PROPER(TRIM(Raw_Data!D13)),Reference_Lists!$B$36:$B$50,0)),"UNMATCHED") -> Nuseirat | E13: =IF(Raw_Data!E13="","",Raw_Data!E13) -> Nutrition | F13: =IF(Raw_Data!F13="","",Raw_Data!F13) -> Complaint | G13: =IF(Raw_Data!G13="","",Raw_Data!G13) -> Non-Sensitive | H13: =IFERROR(INDEX(Reference_Lists!$C$51:$C$57,MATCH(PROPER(TRIM(Raw_Data!H13)),Reference_Lists!$B$51:$B$57,0)),"UNMATCHED") -> Male | I13: =IF(Raw_Data!I13="","",Raw_Data!I13) | J13: =IFERROR(INDEX(Reference_Lists!$C$58:$C$65,MATCH(PROPER(TRIM(Raw_Data!J13)),Reference_Lists!$B$58:$B$65,0)),"UNMATCHED") -> Closed | K13: =IF(Raw_Data!K13="","",IF(ISTEXT(Raw_Data!K13),IFERROR(DATE(VALUE(RIGHT(TRIM(Raw_Data!K13),4)),VALUE(MID(TRIM(Raw_Data!K13),4,2)),VALUE(LEFT(TRIM(Raw_Data!K13),2))),"CHECK"),Raw_Data!K13)) -> 46224 | L13: =IF(Raw_Data!L13="","",Raw_Data!L13) -> Requesting a screening session closer to the northern shelter. | M13: =IF(OR(B13="",K13=""),"",IFERROR(K13-B13,"CHECK")) -> 24 | N13: =IFERROR(INDEX(Reference_Lists!$H$13:$H$14,MATCH(G13,Reference_Lists!$G$13:$G$14,0)),"UNMATCHED") -> 15 | O13: =IF(AND(J13="Closed",ISNUMBER(M13),ISNUMBER(N13),M13>=0),M13<=N13,"NOT ASSESSED") -> FALSE | P13: =Raw_Data!A13 -> CFM-2026-0407 | Q13: =IFERROR(IF(OR($A13="",$P13=""),"MISSING ID",IF(EXACT($A13,$P13),"ALIGNED","MISMATCH")),"CHECK") -> ALIGNED
... A141: CFM-2026-0225 | B141: =IF(Raw_Data!B141="","",IF(ISTEXT(Raw_Data!B141),IFERROR(DATE(VALUE(RIGHT(TRIM(Raw_Data!B141),4)),VALUE(MID(TRIM(Raw_Data!B141),4,2)),VALUE(LEFT(TRIM(Raw_Data!B141),2))),"CHECK"),Raw_Data!B141)) -> 46163 | C141: =IFERROR(INDEX(Reference_Lists!$C$23:$C$35,MATCH(PROPER(TRIM(Raw_Data!C141)),Reference_Lists!$B$23:$B$35,0)),"UNMATCHED") -> Suggestion Box | D141: =IFERROR(INDEX(Reference_Lists!$C$36:$C$50,MATCH(PROPER(TRIM(Raw_Data!D141)),Reference_Lists!$B$36:$B$50,0)),"UNMATCHED") -> Jabalia | E141: =IF(Raw_Data!E141="","",Raw_Data!E141) -> Health | F141: =IF(Raw_Data!F141="","",Raw_Data!F141) -> Complaint | G141: =IF(Raw_Data!G141="","",Raw_Data!G141) -> Non-Sensitive | H141: =IFERROR(INDEX(Reference_Lists!$C$51:$C$57,MATCH(PROPER(TRIM(Raw_Data!H141)),Reference_Lists!$B$51:$B$57,0)),"UNMATCHED") -> Female | I141: =IF(Raw_Data!I141="","",Raw_Data!I141) | J141: =IFERROR(INDEX(Reference_Lists!$C$58:$C$65,MATCH(PROPER(TRIM(Raw_Data!J141)),Reference_Lists!$B$58:$B$65,0)),"UNMATCHED") -> Closed | K141: =IF(Raw_Data!K141="","",IF(ISTEXT(Raw_Data!K141),IFERROR(DATE(VALUE(RIGHT(TRIM(Raw_Data!K141),4)),VALUE(MID(TRIM(Raw_Data!K141),4,2)),VALUE(LEFT(TRIM(Raw_Data!K141),2))),"CHECK"),Raw_Data!K141)) -> 46181 | L141: =IF(Raw_Data!L141="","",Raw_Data!L141) -> Clinic opening hours are not clear to the community. | M141: =IF(OR(B141="",K141=""),"",IFERROR(K141-B141,"CHECK")) -> 18 | N141: =IFERROR(INDEX(Reference_Lists!$H$13:$H$14,MATCH(G141,Reference_Lists!$G$13:$G$14,0)),"UNMATCHED") -> 15 | O141: =IF(AND(J141="Closed",ISNUMBER(M141),ISNUMBER(N141),M141>=0),M141<=N141,"NOT ASSESSED") -> FALSE | P141: =Raw_Data!A141 -> CFM-2026-0225 | Q141: =IFERROR(IF(OR($A141="",$P141=""),"MISSING ID",IF(EXACT($A141,$P141),"ALIGNED","MISMATCH")),"CHECK") -> ALIGNED
A142: CFM-2026-0104 | B142: =IF(Raw_Data!B143="","",IF(ISTEXT(Raw_Data!B143),IFERROR(DATE(VALUE(RIGHT(TRIM(Raw_Data!B143),4)),VALUE(MID(TRIM(Raw_Data!B143),4,2)),VALUE(LEFT(TRIM(Raw_Data!B143),2))),"CHECK"),Raw_Data!B143)) -> 46099 | C142: =IFERROR(INDEX(Reference_Lists!$C$23:$C$35,MATCH(PROPER(TRIM(Raw_Data!C143)),Reference_Lists!$B$23:$B$35,0)),"UNMATCHED") -> Help Desk | D142: =IFERROR(INDEX(Reference_Lists!$C$36:$C$50,MATCH(PROPER(TRIM(Raw_Data!D143)),Reference_Lists!$B$36:$B$50,0)),"UNMATCHED") -> Deir al-Balah | E142: =IF(Raw_Data!E143="","",Raw_Data!E143) -> Nutrition | F142: =IF(Raw_Data!F143="","",Raw_Data!F143) -> Suggestion | G142: =IF(Raw_Data!G143="","",Raw_Data!G143) -> Non-Sensitive | H142: =IFERROR(INDEX(Reference_Lists!$C$51:$C$57,MATCH(PROPER(TRIM(Raw_Data!H143)),Reference_Lists!$B$51:$B$57,0)),"UNMATCHED") -> Male | I142: =IF(Raw_Data!I143="","",Raw_Data!I143) -> 30-44 | J142: =IFERROR(INDEX(Reference_Lists!$C$58:$C$65,MATCH(PROPER(TRIM(Raw_Data!J143)),Reference_Lists!$B$58:$B$65,0)),"UNMATCHED") -> Open | K142: =IF(Raw_Data!K143="","",IF(ISTEXT(Raw_Data!K143),IFERROR(DATE(VALUE(RIGHT(TRIM(Raw_Data!K143),4)),VALUE(MID(TRIM(Raw_Data!K143),4,2)),VALUE(LEFT(TRIM(Raw_Data!K143),2))),"CHECK"),Raw_Data!K143)) | L142: =IF(Raw_Data!L143="","",Raw_Data!L143) -> Asking whether children above five are included in the screening. | M142: =IF(OR(B142="",K142=""),"",IFERROR(K142-B142,"CHECK")) | N142: =IFERROR(INDEX(Reference_Lists!$H$13:$H$14,MATCH(G142,Reference_Lists!$G$13:$G$14,0)),"UNMATCHED") -> 15 | O142: =IF(AND(J142="Closed",ISNUMBER(M142),ISNUMBER(N142),M142>=0),M142<=N142,"NOT ASSESSED") -> NOT ASSESSED | P142: =Raw_Data!A143 -> CFM-2026-0104 | Q142: =IFERROR(IF(OR($A142="",$P142=""),"MISSING ID",IF(EXACT($A142,$P142),"ALIGNED","MISMATCH")),"CHECK") -> ALIGNED
A143: CFM-2026-0145 | B143: =IF(Raw_Data!B144="","",IF(ISTEXT(Raw_Data!B144),IFERROR(DATE(VALUE(RIGHT(TRIM(Raw_Data!B144),4)),VALUE(MID(TRIM(Raw_Data!B144),4,2)),VALUE(LEFT(TRIM(Raw_Data!B144),2))),"CHECK"),Raw_Data!B144)) -> 46085 | C143: =IFERROR(INDEX(Reference_Lists!$C$23:$C$35,MATCH(PROPER(TRIM(Raw_Data!C144)),Reference_Lists!$B$23:$B$35,0)),"UNMATCHED") -> In-Person at Distribution | D143: =IFERROR(INDEX(Reference_Lists!$C$36:$C$50,MATCH(PROPER(TRIM(Raw_Data!D144)),Reference_Lists!$B$36:$B$50,0)),"UNMATCHED") -> Nuseirat | E143: =IF(Raw_Data!E144="","",Raw_Data!E144) -> Food Security | F143: =IF(Raw_Data!F144="","",Raw_Data!F144) -> Complaint | G143: =IF(Raw_Data!G144="","",Raw_Data!G144) -> Non-Sensitive | H143: =IFERROR(INDEX(Reference_Lists!$C$51:$C$57,MATCH(PROPER(TRIM(Raw_Data!H144)),Reference_Lists!$B$51:$B$57,0)),"UNMATCHED") -> Male | I143: =IF(Raw_Data!I144="","",Raw_Data!I144) | J143: =IFERROR(INDEX(Reference_Lists!$C$58:$C$65,MATCH(PROPER(TRIM(Raw_Data!J144)),Reference_Lists!$B$58:$B$65,0)),"UNMATCHED") -> Closed | K143: =IF(Raw_Data!K144="","",IF(ISTEXT(Raw_Data!K144),IFERROR(DATE(VALUE(RIGHT(TRIM(Raw_Data!K144),4)),VALUE(MID(TRIM(Raw_Data!K144),4,2)),VALUE(LEFT(TRIM(Raw_Data!K144),2))),"CHECK"),Raw_Data!K144)) -> 46095 | L143: =IF(Raw_Data!L144="","",Raw_Data!L144) -> Food parcel contents did not match the announced list. | M143: =IF(OR(B143="",K143=""),"",IFERROR(K143-B143,"CHECK")) -> 10 | N143: =IFERROR(INDEX(Reference_Lists!$H$13:$H$14,MATCH(G143,Reference_Lists!$G$13:$G$14,0)),"UNMATCHED") -> 15 | O143: =IF(AND(J143="Closed",ISNUMBER(M143),ISNUMBER(N143),M143>=0),M143<=N143,"NOT ASSESSED") -> TRUE | P143: =Raw_Data!A144 -> CFM-2026-0145 | Q143: =IFERROR(IF(OR($A143="",$P143=""),"MISSING ID",IF(EXACT($A143,$P143),"ALIGNED","MISMATCH")),"CHECK") -> ALIGNED
A144: CFM-2026-0453 | B144: =IF(Raw_Data!B145="","",IF(ISTEXT(Raw_Data!B145),IFERROR(DATE(VALUE(RIGHT(TRIM(Raw_Data!B145),4)),VALUE(MID(TRIM(Raw_Data!B145),4,2)),VALUE(LEFT(TRIM(Raw_Data!B145),2))),"CHECK"),Raw_Data!B145)) -> 46055 | C144: =IFERROR(INDEX(Reference_Lists!$C$23:$C$35,MATCH(PROPER(TRIM(Raw_Data!C145)),Reference_Lists!$B$23:$B$35,0)),"UNMATCHED") -> In-Person at Distribution | D144: =IFERROR(INDEX(Reference_Lists!$C$36:$C$50,MATCH(PROPER(TRIM(Raw_Data!D145)),Reference_Lists!$B$36:$B$50,0)),"UNMATCHED") -> Gaza City | E144: =IF(Raw_Data!E145="","",Raw_Data!E145) -> Health | F144: =IF(Raw_Data!F145="","",Raw_Data!F145) -> Suggestion | G144: =IF(Raw_Data!G145="","",Raw_Data!G145) -> Non-Sensitive | H144: =IFERROR(INDEX(Reference_Lists!$C$51:$C$57,MATCH(PROPER(TRIM(Raw_Data!H145)),Reference_Lists!$B$51:$B$57,0)),"UNMATCHED") -> Male | I144: =IF(Raw_Data!I145="","",Raw_Data!I145) -> 45-59 | J144: =IFERROR(INDEX(Reference_Lists!$C$58:$C$65,MATCH(PROPER(TRIM(Raw_Data!J145)),Reference_Lists!$B$58:$B$65,0)),"UNMATCHED") -> Closed | K144: =IF(Raw_Data!K145="","",IF(ISTEXT(Raw_Data!K145),IFERROR(DATE(VALUE(RIGHT(TRIM(Raw_Data!K145),4)),VALUE(MID(TRIM(Raw_Data!K145),4,2)),VALUE(LEFT(TRIM(Raw_Data!K145),2))),"CHECK"),Raw_Data!K145)) -> 46060 | L144: =IF(Raw_Data!L145="","",Raw_Data!L145) -> Waiting time at the mobile clinic is long during afternoon hours. | M144: =IF(OR(B144="",K144=""),"",IFERROR(K144-B144,"CHECK")) -> 5 | N144: =IFERROR(INDEX(Reference_Lists!$H$13:$H$14,MATCH(G144,Reference_Lists!$G$13:$G$14,0)),"UNMATCHED") -> 15 | O144: =IF(AND(J144="Closed",ISNUMBER(M144),ISNUMBER(N144),M144>=0),M144<=N144,"NOT ASSESSED") -> TRUE | P144: =Raw_Data!A145 -> CFM-2026-0453 | Q144: =IFERROR(IF(OR($A144="",$P144=""),"MISSING ID",IF(EXACT($A144,$P144),"ALIGNED","MISMATCH")),"CHECK") -> ALIGNED
A145: CFM-2026-0478 | B145: =IF(Raw_Data!B146="","",IF(ISTEXT(Raw_Data!B146),IFERROR(DATE(VALUE(RIGHT(TRIM(Raw_Data!B146),4)),VALUE(MID(TRIM(Raw_Data!B146),4,2)),VALUE(LEFT(TRIM(Raw_Data!B146),2))),"CHECK"),Raw_Data!B146)) -> 46198 | C145: =IFERROR(INDEX(Reference_Lists!$C$23:$C$35,MATCH(PROPER(TRIM(Raw_Data!C146)),Reference_Lists!$B$23:$B$35,0)),"UNMATCHED") -> Help Desk | D145: =IFERROR(INDEX(Reference_Lists!$C$36:$C$50,MATCH(PROPER(TRIM(Raw_Data!D146)),Reference_Lists!$B$36:$B$50,0)),"UNMATCHED") -> Jabalia | E145: =IF(Raw_Data!E146="","",Raw_Data!E146) -> Nutrition | F145: =IF(Raw_Data!F146="","",Raw_Data!F146) -> Suggestion | G145: =IF(Raw_Data!G146="","",Raw_Data!G146) | H145: =IFERROR(INDEX(Reference_Lists!$C$51:$C$57,MATCH(PROPER(TRIM(Raw_Data!H146)),Reference_Lists!$B$51:$B$57,0)),"UNMATCHED") -> Male | I145: =IF(Raw_Data!I146="","",Raw_Data!I146) -> 18-29 | J145: =IFERROR(INDEX(Reference_Lists!$C$58:$C$65,MATCH(PROPER(TRIM(Raw_Data!J146)),Reference_Lists!$B$58:$B$65,0)),"UNMATCHED") -> Closed | K145: =IF(Raw_Data!K146="","",IF(ISTEXT(Raw_Data!K146),IFERROR(DATE(VALUE(RIGHT(TRIM(Raw_Data!K146),4)),VALUE(MID(TRIM(Raw_Data!K146),4,2)),VALUE(LEFT(TRIM(Raw_Data!K146),2))),"CHECK"),Raw_Data!K146)) -> 46199 | L145: =IF(Raw_Data!L146="","",Raw_Data!L146) -> Asking whether children above five are included in the screening. | M145: =IF(OR(B145="",K145=""),"",IFERROR(K145-B145,"CHECK")) -> 1 | N145: =IFERROR(INDEX(Reference_Lists!$H$13:$H$14,MATCH(G145,Reference_Lists!$G$13:$G$14,0)),"UNMATCHED") -> UNMATCHED | O145: =IF(AND(J145="Closed",ISNUMBER(M145),ISNUMBER(N145),M145>=0),M145<=N145,"NOT ASSESSED") -> NOT ASSESSED | P145: =Raw_Data!A146 -> CFM-2026-0478 | Q145: =IFERROR(IF(OR($A145="",$P145=""),"MISSING ID",IF(EXACT($A145,$P145),"ALIGNED","MISMATCH")),"CHECK") -> ALIGNED
A146: CFM-2026-0361 | B146: =IF(Raw_Data!B147="","",IF(ISTEXT(Raw_Data!B147),IFERROR(DATE(VALUE(RIGHT(TRIM(Raw_Data!B147),4)),VALUE(MID(TRIM(Raw_Data!B147),4,2)),VALUE(LEFT(TRIM(Raw_Data!B147),2))),"CHECK"),Raw_Data!B147)) -> 46221 | C146: =IFERROR(INDEX(Reference_Lists!$C$23:$C$35,MATCH(PROPER(TRIM(Raw_Data!C147)),Reference_Lists!$B$23:$B$35,0)),"UNMATCHED") -> Suggestion Box | D146: =IFERROR(INDEX(Reference_Lists!$C$36:$C$50,MATCH(PROPER(TRIM(Raw_Data!D147)),Reference_Lists!$B$36:$B$50,0)),"UNMATCHED") -> Jabalia | E146: =IF(Raw_Data!E147="","",Raw_Data!E147) -> WASH | F146: =IF(Raw_Data!F147="","",Raw_Data!F147) -> Complaint | G146: =IF(Raw_Data!G147="","",Raw_Data!G147) -> Non-Sensitive | H146: =IFERROR(INDEX(Reference_Lists!$C$51:$C$57,MATCH(PROPER(TRIM(Raw_Data!H147)),Reference_Lists!$B$51:$B$57,0)),"UNMATCHED") -> Female | I146: =IF(Raw_Data!I147="","",Raw_Data!I147) -> 30-44 | J146: =IFERROR(INDEX(Reference_Lists!$C$58:$C$65,MATCH(PROPER(TRIM(Raw_Data!J147)),Reference_Lists!$B$58:$B$65,0)),"UNMATCHED") -> Open | K146: =IF(Raw_Data!K147="","",IF(ISTEXT(Raw_Data!K147),IFERROR(DATE(VALUE(RIGHT(TRIM(Raw_Data!K147),4)),VALUE(MID(TRIM(Raw_Data!K147),4,2)),VALUE(LEFT(TRIM(Raw_Data!K147),2))),"CHECK"),Raw_Data!K147)) | L146: =IF(Raw_Data!L147="","",Raw_Data!L147) -> The queue at the water point is not organised and older people cannot wait. | M146: =IF(OR(B146="",K146=""),"",IFERROR(K146-B146,"CHECK")) | N146: =IFERROR(INDEX(Reference_Lists!$H$13:$H$14,MATCH(G146,Reference_Lists!$G$13:$G$14,0)),"UNMATCHED") -> 15 | O146: =IF(AND(J146="Closed",ISNUMBER(M146),ISNUMBER(N146),M146>=0),M146<=N146,"NOT ASSESSED") -> NOT ASSESSED | P146: =Raw_Data!A147 -> CFM-2026-0361 | Q146: =IFERROR(IF(OR($A146="",$P146=""),"MISSING ID",IF(EXACT($A146,$P146),"ALIGNED","MISMATCH")),"CHECK") -> ALIGNED
